<?xml version="1.0"?>
<robot xmlns:xacro="http://www.ros.org/wiki/xacro" name="jazzy_bot">

    <material name="blue"> <color rgba="0 0 0.8 1"/> </material>
    <material name="black"> <color rgba="0 0 0 1"/> </material>

    <xacro:property name="base_width" value="0.4"/>
    <xacro:property name="base_length" value="0.6"/>
    <xacro:property name="base_height" value="0.2"/>
    <xacro:property name="wheel_radius" value="0.1"/>
    <xacro:property name="wheel_width" value="0.05"/>
    <xacro:property name="wheel_ygap" value="0.05"/>
    <xacro:property name="wheel_zoff" value="0.05"/>
    <xacro:property name="wheel_xoff" value="0.2"/>

    <xacro:macro name="box_inertia" params="m w h d">
        <inertial>
            <origin xyz="0 0 0" rpy="${pi/2} 0 ${pi/2}"/>
            <mass value="${m}"/>
            <inertia ixx="${(m/12) * (h*h + d*d)}" ixy="0.0" ixz="0.0" iyy="${(m/12) * (w*w + d*d)}" iyz="0.0" izz="${(m/12) * (w*w + h*h)}"/>
        </inertial>
    </xacro:macro>

    <xacro:macro name="cylinder_inertia" params="m r h">
        <inertial>
            <origin xyz="0 0 0" rpy="${pi/2} 0 0" />
            <mass value="${m}"/>
            <inertia ixx="${(m/12) * (3*r*r + h*h)}" ixy="0" ixz="0" iyy="${(m/12) * (3*r*r + h*h)}" iyz="0" izz="${(m/2) * (r*r)}"/>
        </inertial>
    </xacro:macro>

    <link name="base_footprint"/>

    <joint name="base_joint" type="fixed">
        <parent link="base_footprint"/>
        <child link="base_link"/>
        <origin xyz="0 0 ${wheel_radius}" rpy="0 0 0"/>
    </joint>

    <link name="base_link">
        <visual>
            <geometry> <box size="${base_length} ${base_width} ${base_height}"/> </geometry>
            <material name="blue"/>
        </visual>
        <collision>
            <geometry> <box size="${base_length} ${base_width} ${base_height}"/> </geometry>
        </collision>
        <xacro:box_inertia m="15" w="${base_width}" h="${base_height}" d="${base_length}"/>
    </link>

    <xacro:macro name="wheel" params="prefix x_reflect y_reflect">
        <link name="${prefix}_wheel">
            <visual>
                <origin xyz="0 0 0" rpy="${pi/2} 0 0"/>
                <geometry> <cylinder radius="${wheel_radius}" length="${wheel_width}"/> </geometry>
                <material name="black"/>
            </visual>
            <collision>
                <origin xyz="0 0 0" rpy="${pi/2} 0 0"/>
                <geometry> <cylinder radius="${wheel_radius}" length="${wheel_width}"/> </geometry>
            </collision>
            <xacro:cylinder_inertia m="0.5" r="${wheel_radius}" h="${wheel_width}"/>
        </link>

        <joint name="${prefix}_wheel_joint" type="continuous">
            <parent link="base_link"/>
            <child link="${prefix}_wheel"/>
            <origin xyz="${x_reflect*wheel_xoff} ${y_reflect*(base_width/2+wheel_ygap)} ${-wheel_zoff}" rpy="0 0 0"/>
            <axis xyz="0 1 0"/>
        </joint>
    </xacro:macro>

    <xacro:wheel prefix="front_left"  x_reflect="1"  y_reflect="1" />
    <xacro:wheel prefix="front_right" x_reflect="1"  y_reflect="-1" />
    <xacro:wheel prefix="rear_left"   x_reflect="-1" y_reflect="1" />
    <xacro:wheel prefix="rear_right"  x_reflect="-1" y_reflect="-1" />

    <xacro:macro name="ros2_control_config" params="use_sim">

        <ros2_control name="DiffDriveSystem" type="system">
            <hardware>
                <xacro:if value="${use_sim}">
                    <plugin>gz_ros2_control/GazeboSimSystem</plugin>
                </xacro:if>
                <xacro:unless value="${use_sim}">
                    <plugin>diff_drive_robot/DiffDriveHardware</plugin>
                    <param name="serial_port">/dev/ttyUSB0</param>
                    <param name="baud_rate">115200</param>
                </xacro:unless>
            </hardware>
            <joint name="front_left_wheel_joint">
                <command_interface name="velocity"/>
                <state_interface name="position"/>
                <state_interface name="velocity"/>
            </joint>
            <joint name="rear_left_wheel_joint">
                <command_interface name="velocity"/>
                <state_interface name="position"/>
                <state_interface name="velocity"/>
            </joint>
            <joint name="front_right_wheel_joint">
                <command_interface name="velocity"/>
                <state_interface name="position"/>
                <state_interface name="velocity"/>
            </joint>
            <joint name="rear_right_wheel_joint">
                <command_interface name="velocity"/>
                <state_interface name="position"/>
                <state_interface name="velocity"/>
            </joint>
        </ros2_control>

        <xacro:if value="${use_sim}">
            <gazebo>
                <plugin filename="gz_ros2_control-system"
                    name="gz_ros2_control::GazeboSimROS2ControlPlugin">
                    <parameters>$(find mobile_robot_description)/config/controllers.yaml</parameters>
                </plugin>
            </gazebo>
        </xacro:if>
    </xacro:macro>
</robot>